[2022-02-02 20:26:50,694] {scheduler_job.py:155} INFO - Started process (PID=6824) to work on /mnt/d/Alura/engenharia-dados-apache-airflow/datapipeline/airflow/dags/twitter_dag.py
[2022-02-02 20:26:50,699] {scheduler_job.py:1572} INFO - Processing file /mnt/d/Alura/engenharia-dados-apache-airflow/datapipeline/airflow/dags/twitter_dag.py for tasks to queue
[2022-02-02 20:26:50,701] {logging_mixin.py:112} INFO - [2022-02-02 20:26:50,700] {dagbag.py:417} INFO - Filling up the DagBag from /mnt/d/Alura/engenharia-dados-apache-airflow/datapipeline/airflow/dags/twitter_dag.py
[2022-02-02 20:26:50,711] {logging_mixin.py:112} INFO - [2022-02-02 20:26:50,709] {dagbag.py:259} ERROR - Failed to import: /mnt/d/Alura/engenharia-dados-apache-airflow/datapipeline/airflow/dags/twitter_dag.py
Traceback (most recent call last):
  File "/mnt/d/Alura/engenharia-dados-apache-airflow/datapipeline/.env/lib/python3.7/site-packages/airflow/models/dagbag.py", line 256, in process_file
    m = imp.load_source(mod_name, filepath)
  File "/home/felipe/anaconda3/lib/python3.7/imp.py", line 171, in load_source
    module = _load(spec)
  File "<frozen importlib._bootstrap>", line 696, in _load
  File "<frozen importlib._bootstrap>", line 677, in _load_unlocked
  File "<frozen importlib._bootstrap_external>", line 728, in exec_module
  File "<frozen importlib._bootstrap>", line 219, in _call_with_frames_removed
  File "/mnt/d/Alura/engenharia-dados-apache-airflow/datapipeline/airflow/dags/twitter_dag.py", line 4, in <module>
    from airflow.operators.alura import TwitterOperator
ModuleNotFoundError: No module named 'airflow.operators.alura'
[2022-02-02 20:26:50,712] {scheduler_job.py:1586} WARNING - No viable dags retrieved from /mnt/d/Alura/engenharia-dados-apache-airflow/datapipeline/airflow/dags/twitter_dag.py
[2022-02-02 20:26:50,730] {scheduler_job.py:163} INFO - Processing /mnt/d/Alura/engenharia-dados-apache-airflow/datapipeline/airflow/dags/twitter_dag.py took 0.037 seconds
[2022-02-02 20:27:42,706] {scheduler_job.py:155} INFO - Started process (PID=6875) to work on /mnt/d/Alura/engenharia-dados-apache-airflow/datapipeline/airflow/dags/twitter_dag.py
[2022-02-02 20:27:42,709] {scheduler_job.py:1572} INFO - Processing file /mnt/d/Alura/engenharia-dados-apache-airflow/datapipeline/airflow/dags/twitter_dag.py for tasks to queue
[2022-02-02 20:27:42,709] {logging_mixin.py:112} INFO - [2022-02-02 20:27:42,709] {dagbag.py:417} INFO - Filling up the DagBag from /mnt/d/Alura/engenharia-dados-apache-airflow/datapipeline/airflow/dags/twitter_dag.py
[2022-02-02 20:27:42,713] {logging_mixin.py:112} INFO - [2022-02-02 20:27:42,712] {dagbag.py:259} ERROR - Failed to import: /mnt/d/Alura/engenharia-dados-apache-airflow/datapipeline/airflow/dags/twitter_dag.py
Traceback (most recent call last):
  File "/mnt/d/Alura/engenharia-dados-apache-airflow/datapipeline/.env/lib/python3.7/site-packages/airflow/models/dagbag.py", line 256, in process_file
    m = imp.load_source(mod_name, filepath)
  File "/home/felipe/anaconda3/lib/python3.7/imp.py", line 171, in load_source
    module = _load(spec)
  File "<frozen importlib._bootstrap>", line 696, in _load
  File "<frozen importlib._bootstrap>", line 677, in _load_unlocked
  File "<frozen importlib._bootstrap_external>", line 728, in exec_module
  File "<frozen importlib._bootstrap>", line 219, in _call_with_frames_removed
  File "/mnt/d/Alura/engenharia-dados-apache-airflow/datapipeline/airflow/dags/twitter_dag.py", line 4, in <module>
    from airflow.operators.alura import TwitterOperator
ModuleNotFoundError: No module named 'airflow.operators.alura'
[2022-02-02 20:27:42,713] {scheduler_job.py:1586} WARNING - No viable dags retrieved from /mnt/d/Alura/engenharia-dados-apache-airflow/datapipeline/airflow/dags/twitter_dag.py
[2022-02-02 20:27:42,727] {scheduler_job.py:163} INFO - Processing /mnt/d/Alura/engenharia-dados-apache-airflow/datapipeline/airflow/dags/twitter_dag.py took 0.022 seconds
[2022-02-02 20:28:34,737] {scheduler_job.py:155} INFO - Started process (PID=6917) to work on /mnt/d/Alura/engenharia-dados-apache-airflow/datapipeline/airflow/dags/twitter_dag.py
[2022-02-02 20:28:34,740] {scheduler_job.py:1572} INFO - Processing file /mnt/d/Alura/engenharia-dados-apache-airflow/datapipeline/airflow/dags/twitter_dag.py for tasks to queue
[2022-02-02 20:28:34,741] {logging_mixin.py:112} INFO - [2022-02-02 20:28:34,741] {dagbag.py:417} INFO - Filling up the DagBag from /mnt/d/Alura/engenharia-dados-apache-airflow/datapipeline/airflow/dags/twitter_dag.py
[2022-02-02 20:28:34,744] {logging_mixin.py:112} INFO - [2022-02-02 20:28:34,743] {dagbag.py:259} ERROR - Failed to import: /mnt/d/Alura/engenharia-dados-apache-airflow/datapipeline/airflow/dags/twitter_dag.py
Traceback (most recent call last):
  File "/mnt/d/Alura/engenharia-dados-apache-airflow/datapipeline/.env/lib/python3.7/site-packages/airflow/models/dagbag.py", line 256, in process_file
    m = imp.load_source(mod_name, filepath)
  File "/home/felipe/anaconda3/lib/python3.7/imp.py", line 171, in load_source
    module = _load(spec)
  File "<frozen importlib._bootstrap>", line 696, in _load
  File "<frozen importlib._bootstrap>", line 677, in _load_unlocked
  File "<frozen importlib._bootstrap_external>", line 728, in exec_module
  File "<frozen importlib._bootstrap>", line 219, in _call_with_frames_removed
  File "/mnt/d/Alura/engenharia-dados-apache-airflow/datapipeline/airflow/dags/twitter_dag.py", line 4, in <module>
    from airflow.operators.alura import TwitterOperator
ModuleNotFoundError: No module named 'airflow.operators.alura'
[2022-02-02 20:28:34,744] {scheduler_job.py:1586} WARNING - No viable dags retrieved from /mnt/d/Alura/engenharia-dados-apache-airflow/datapipeline/airflow/dags/twitter_dag.py
[2022-02-02 20:28:34,755] {scheduler_job.py:163} INFO - Processing /mnt/d/Alura/engenharia-dados-apache-airflow/datapipeline/airflow/dags/twitter_dag.py took 0.018 seconds
[2022-02-02 20:29:26,766] {scheduler_job.py:155} INFO - Started process (PID=6965) to work on /mnt/d/Alura/engenharia-dados-apache-airflow/datapipeline/airflow/dags/twitter_dag.py
[2022-02-02 20:29:26,769] {scheduler_job.py:1572} INFO - Processing file /mnt/d/Alura/engenharia-dados-apache-airflow/datapipeline/airflow/dags/twitter_dag.py for tasks to queue
[2022-02-02 20:29:26,769] {logging_mixin.py:112} INFO - [2022-02-02 20:29:26,769] {dagbag.py:417} INFO - Filling up the DagBag from /mnt/d/Alura/engenharia-dados-apache-airflow/datapipeline/airflow/dags/twitter_dag.py
[2022-02-02 20:29:26,773] {logging_mixin.py:112} INFO - [2022-02-02 20:29:26,772] {dagbag.py:259} ERROR - Failed to import: /mnt/d/Alura/engenharia-dados-apache-airflow/datapipeline/airflow/dags/twitter_dag.py
Traceback (most recent call last):
  File "/mnt/d/Alura/engenharia-dados-apache-airflow/datapipeline/.env/lib/python3.7/site-packages/airflow/models/dagbag.py", line 256, in process_file
    m = imp.load_source(mod_name, filepath)
  File "/home/felipe/anaconda3/lib/python3.7/imp.py", line 171, in load_source
    module = _load(spec)
  File "<frozen importlib._bootstrap>", line 696, in _load
  File "<frozen importlib._bootstrap>", line 677, in _load_unlocked
  File "<frozen importlib._bootstrap_external>", line 728, in exec_module
  File "<frozen importlib._bootstrap>", line 219, in _call_with_frames_removed
  File "/mnt/d/Alura/engenharia-dados-apache-airflow/datapipeline/airflow/dags/twitter_dag.py", line 4, in <module>
    from airflow.operators.alura import TwitterOperator
ModuleNotFoundError: No module named 'airflow.operators.alura'
[2022-02-02 20:29:26,773] {scheduler_job.py:1586} WARNING - No viable dags retrieved from /mnt/d/Alura/engenharia-dados-apache-airflow/datapipeline/airflow/dags/twitter_dag.py
[2022-02-02 20:29:26,785] {scheduler_job.py:163} INFO - Processing /mnt/d/Alura/engenharia-dados-apache-airflow/datapipeline/airflow/dags/twitter_dag.py took 0.019 seconds
[2022-02-02 20:30:18,794] {scheduler_job.py:155} INFO - Started process (PID=7001) to work on /mnt/d/Alura/engenharia-dados-apache-airflow/datapipeline/airflow/dags/twitter_dag.py
[2022-02-02 20:30:18,798] {scheduler_job.py:1572} INFO - Processing file /mnt/d/Alura/engenharia-dados-apache-airflow/datapipeline/airflow/dags/twitter_dag.py for tasks to queue
[2022-02-02 20:30:18,798] {logging_mixin.py:112} INFO - [2022-02-02 20:30:18,798] {dagbag.py:417} INFO - Filling up the DagBag from /mnt/d/Alura/engenharia-dados-apache-airflow/datapipeline/airflow/dags/twitter_dag.py
[2022-02-02 20:30:18,802] {logging_mixin.py:112} INFO - [2022-02-02 20:30:18,800] {dagbag.py:259} ERROR - Failed to import: /mnt/d/Alura/engenharia-dados-apache-airflow/datapipeline/airflow/dags/twitter_dag.py
Traceback (most recent call last):
  File "/mnt/d/Alura/engenharia-dados-apache-airflow/datapipeline/.env/lib/python3.7/site-packages/airflow/models/dagbag.py", line 256, in process_file
    m = imp.load_source(mod_name, filepath)
  File "/home/felipe/anaconda3/lib/python3.7/imp.py", line 171, in load_source
    module = _load(spec)
  File "<frozen importlib._bootstrap>", line 696, in _load
  File "<frozen importlib._bootstrap>", line 677, in _load_unlocked
  File "<frozen importlib._bootstrap_external>", line 728, in exec_module
  File "<frozen importlib._bootstrap>", line 219, in _call_with_frames_removed
  File "/mnt/d/Alura/engenharia-dados-apache-airflow/datapipeline/airflow/dags/twitter_dag.py", line 4, in <module>
    from airflow.operators.alura import TwitterOperator
ModuleNotFoundError: No module named 'airflow.operators.alura'
[2022-02-02 20:30:18,802] {scheduler_job.py:1586} WARNING - No viable dags retrieved from /mnt/d/Alura/engenharia-dados-apache-airflow/datapipeline/airflow/dags/twitter_dag.py
[2022-02-02 20:30:18,814] {scheduler_job.py:163} INFO - Processing /mnt/d/Alura/engenharia-dados-apache-airflow/datapipeline/airflow/dags/twitter_dag.py took 0.020 seconds
[2022-02-02 20:31:10,826] {scheduler_job.py:155} INFO - Started process (PID=7044) to work on /mnt/d/Alura/engenharia-dados-apache-airflow/datapipeline/airflow/dags/twitter_dag.py
[2022-02-02 20:31:10,829] {scheduler_job.py:1572} INFO - Processing file /mnt/d/Alura/engenharia-dados-apache-airflow/datapipeline/airflow/dags/twitter_dag.py for tasks to queue
[2022-02-02 20:31:10,829] {logging_mixin.py:112} INFO - [2022-02-02 20:31:10,829] {dagbag.py:417} INFO - Filling up the DagBag from /mnt/d/Alura/engenharia-dados-apache-airflow/datapipeline/airflow/dags/twitter_dag.py
[2022-02-02 20:31:10,833] {logging_mixin.py:112} INFO - [2022-02-02 20:31:10,831] {dagbag.py:259} ERROR - Failed to import: /mnt/d/Alura/engenharia-dados-apache-airflow/datapipeline/airflow/dags/twitter_dag.py
Traceback (most recent call last):
  File "/mnt/d/Alura/engenharia-dados-apache-airflow/datapipeline/.env/lib/python3.7/site-packages/airflow/models/dagbag.py", line 256, in process_file
    m = imp.load_source(mod_name, filepath)
  File "/home/felipe/anaconda3/lib/python3.7/imp.py", line 171, in load_source
    module = _load(spec)
  File "<frozen importlib._bootstrap>", line 696, in _load
  File "<frozen importlib._bootstrap>", line 677, in _load_unlocked
  File "<frozen importlib._bootstrap_external>", line 728, in exec_module
  File "<frozen importlib._bootstrap>", line 219, in _call_with_frames_removed
  File "/mnt/d/Alura/engenharia-dados-apache-airflow/datapipeline/airflow/dags/twitter_dag.py", line 4, in <module>
    from airflow.operators.alura import TwitterOperator
ModuleNotFoundError: No module named 'airflow.operators.alura'
[2022-02-02 20:31:10,833] {scheduler_job.py:1586} WARNING - No viable dags retrieved from /mnt/d/Alura/engenharia-dados-apache-airflow/datapipeline/airflow/dags/twitter_dag.py
[2022-02-02 20:31:10,845] {scheduler_job.py:163} INFO - Processing /mnt/d/Alura/engenharia-dados-apache-airflow/datapipeline/airflow/dags/twitter_dag.py took 0.019 seconds
[2022-02-02 20:32:02,857] {scheduler_job.py:155} INFO - Started process (PID=7090) to work on /mnt/d/Alura/engenharia-dados-apache-airflow/datapipeline/airflow/dags/twitter_dag.py
[2022-02-02 20:32:02,860] {scheduler_job.py:1572} INFO - Processing file /mnt/d/Alura/engenharia-dados-apache-airflow/datapipeline/airflow/dags/twitter_dag.py for tasks to queue
[2022-02-02 20:32:02,860] {logging_mixin.py:112} INFO - [2022-02-02 20:32:02,860] {dagbag.py:417} INFO - Filling up the DagBag from /mnt/d/Alura/engenharia-dados-apache-airflow/datapipeline/airflow/dags/twitter_dag.py
[2022-02-02 20:32:02,863] {logging_mixin.py:112} INFO - [2022-02-02 20:32:02,862] {dagbag.py:259} ERROR - Failed to import: /mnt/d/Alura/engenharia-dados-apache-airflow/datapipeline/airflow/dags/twitter_dag.py
Traceback (most recent call last):
  File "/mnt/d/Alura/engenharia-dados-apache-airflow/datapipeline/.env/lib/python3.7/site-packages/airflow/models/dagbag.py", line 256, in process_file
    m = imp.load_source(mod_name, filepath)
  File "/home/felipe/anaconda3/lib/python3.7/imp.py", line 171, in load_source
    module = _load(spec)
  File "<frozen importlib._bootstrap>", line 696, in _load
  File "<frozen importlib._bootstrap>", line 677, in _load_unlocked
  File "<frozen importlib._bootstrap_external>", line 728, in exec_module
  File "<frozen importlib._bootstrap>", line 219, in _call_with_frames_removed
  File "/mnt/d/Alura/engenharia-dados-apache-airflow/datapipeline/airflow/dags/twitter_dag.py", line 4, in <module>
    from airflow.operators.alura import TwitterOperator
ModuleNotFoundError: No module named 'airflow.operators.alura'
[2022-02-02 20:32:02,864] {scheduler_job.py:1586} WARNING - No viable dags retrieved from /mnt/d/Alura/engenharia-dados-apache-airflow/datapipeline/airflow/dags/twitter_dag.py
[2022-02-02 20:32:02,876] {scheduler_job.py:163} INFO - Processing /mnt/d/Alura/engenharia-dados-apache-airflow/datapipeline/airflow/dags/twitter_dag.py took 0.018 seconds
[2022-02-02 20:32:54,881] {scheduler_job.py:155} INFO - Started process (PID=7126) to work on /mnt/d/Alura/engenharia-dados-apache-airflow/datapipeline/airflow/dags/twitter_dag.py
[2022-02-02 20:32:54,884] {scheduler_job.py:1572} INFO - Processing file /mnt/d/Alura/engenharia-dados-apache-airflow/datapipeline/airflow/dags/twitter_dag.py for tasks to queue
[2022-02-02 20:32:54,885] {logging_mixin.py:112} INFO - [2022-02-02 20:32:54,885] {dagbag.py:417} INFO - Filling up the DagBag from /mnt/d/Alura/engenharia-dados-apache-airflow/datapipeline/airflow/dags/twitter_dag.py
[2022-02-02 20:32:54,888] {logging_mixin.py:112} INFO - [2022-02-02 20:32:54,887] {dagbag.py:259} ERROR - Failed to import: /mnt/d/Alura/engenharia-dados-apache-airflow/datapipeline/airflow/dags/twitter_dag.py
Traceback (most recent call last):
  File "/mnt/d/Alura/engenharia-dados-apache-airflow/datapipeline/.env/lib/python3.7/site-packages/airflow/models/dagbag.py", line 256, in process_file
    m = imp.load_source(mod_name, filepath)
  File "/home/felipe/anaconda3/lib/python3.7/imp.py", line 171, in load_source
    module = _load(spec)
  File "<frozen importlib._bootstrap>", line 696, in _load
  File "<frozen importlib._bootstrap>", line 677, in _load_unlocked
  File "<frozen importlib._bootstrap_external>", line 728, in exec_module
  File "<frozen importlib._bootstrap>", line 219, in _call_with_frames_removed
  File "/mnt/d/Alura/engenharia-dados-apache-airflow/datapipeline/airflow/dags/twitter_dag.py", line 4, in <module>
    from airflow.operators.alura import TwitterOperator
ModuleNotFoundError: No module named 'airflow.operators.alura'
[2022-02-02 20:32:54,888] {scheduler_job.py:1586} WARNING - No viable dags retrieved from /mnt/d/Alura/engenharia-dados-apache-airflow/datapipeline/airflow/dags/twitter_dag.py
[2022-02-02 20:32:54,901] {scheduler_job.py:163} INFO - Processing /mnt/d/Alura/engenharia-dados-apache-airflow/datapipeline/airflow/dags/twitter_dag.py took 0.019 seconds
[2022-02-02 20:33:46,940] {scheduler_job.py:155} INFO - Started process (PID=7172) to work on /mnt/d/Alura/engenharia-dados-apache-airflow/datapipeline/airflow/dags/twitter_dag.py
[2022-02-02 20:33:46,944] {scheduler_job.py:1572} INFO - Processing file /mnt/d/Alura/engenharia-dados-apache-airflow/datapipeline/airflow/dags/twitter_dag.py for tasks to queue
[2022-02-02 20:33:46,944] {logging_mixin.py:112} INFO - [2022-02-02 20:33:46,944] {dagbag.py:417} INFO - Filling up the DagBag from /mnt/d/Alura/engenharia-dados-apache-airflow/datapipeline/airflow/dags/twitter_dag.py
[2022-02-02 20:33:46,948] {logging_mixin.py:112} INFO - [2022-02-02 20:33:46,947] {dagbag.py:259} ERROR - Failed to import: /mnt/d/Alura/engenharia-dados-apache-airflow/datapipeline/airflow/dags/twitter_dag.py
Traceback (most recent call last):
  File "/mnt/d/Alura/engenharia-dados-apache-airflow/datapipeline/.env/lib/python3.7/site-packages/airflow/models/dagbag.py", line 256, in process_file
    m = imp.load_source(mod_name, filepath)
  File "/home/felipe/anaconda3/lib/python3.7/imp.py", line 171, in load_source
    module = _load(spec)
  File "<frozen importlib._bootstrap>", line 696, in _load
  File "<frozen importlib._bootstrap>", line 677, in _load_unlocked
  File "<frozen importlib._bootstrap_external>", line 728, in exec_module
  File "<frozen importlib._bootstrap>", line 219, in _call_with_frames_removed
  File "/mnt/d/Alura/engenharia-dados-apache-airflow/datapipeline/airflow/dags/twitter_dag.py", line 4, in <module>
    from airflow.operators.alura import TwitterOperator
ModuleNotFoundError: No module named 'airflow.operators.alura'
[2022-02-02 20:33:46,948] {scheduler_job.py:1586} WARNING - No viable dags retrieved from /mnt/d/Alura/engenharia-dados-apache-airflow/datapipeline/airflow/dags/twitter_dag.py
[2022-02-02 20:33:46,963] {scheduler_job.py:163} INFO - Processing /mnt/d/Alura/engenharia-dados-apache-airflow/datapipeline/airflow/dags/twitter_dag.py took 0.023 seconds
[2022-02-02 20:34:38,962] {scheduler_job.py:155} INFO - Started process (PID=7214) to work on /mnt/d/Alura/engenharia-dados-apache-airflow/datapipeline/airflow/dags/twitter_dag.py
[2022-02-02 20:34:38,966] {scheduler_job.py:1572} INFO - Processing file /mnt/d/Alura/engenharia-dados-apache-airflow/datapipeline/airflow/dags/twitter_dag.py for tasks to queue
[2022-02-02 20:34:38,966] {logging_mixin.py:112} INFO - [2022-02-02 20:34:38,966] {dagbag.py:417} INFO - Filling up the DagBag from /mnt/d/Alura/engenharia-dados-apache-airflow/datapipeline/airflow/dags/twitter_dag.py
[2022-02-02 20:34:38,969] {logging_mixin.py:112} INFO - [2022-02-02 20:34:38,968] {dagbag.py:259} ERROR - Failed to import: /mnt/d/Alura/engenharia-dados-apache-airflow/datapipeline/airflow/dags/twitter_dag.py
Traceback (most recent call last):
  File "/mnt/d/Alura/engenharia-dados-apache-airflow/datapipeline/.env/lib/python3.7/site-packages/airflow/models/dagbag.py", line 256, in process_file
    m = imp.load_source(mod_name, filepath)
  File "/home/felipe/anaconda3/lib/python3.7/imp.py", line 171, in load_source
    module = _load(spec)
  File "<frozen importlib._bootstrap>", line 696, in _load
  File "<frozen importlib._bootstrap>", line 677, in _load_unlocked
  File "<frozen importlib._bootstrap_external>", line 728, in exec_module
  File "<frozen importlib._bootstrap>", line 219, in _call_with_frames_removed
  File "/mnt/d/Alura/engenharia-dados-apache-airflow/datapipeline/airflow/dags/twitter_dag.py", line 4, in <module>
    from airflow.operators.alura import TwitterOperator
ModuleNotFoundError: No module named 'airflow.operators.alura'
[2022-02-02 20:34:38,969] {scheduler_job.py:1586} WARNING - No viable dags retrieved from /mnt/d/Alura/engenharia-dados-apache-airflow/datapipeline/airflow/dags/twitter_dag.py
[2022-02-02 20:34:38,981] {scheduler_job.py:163} INFO - Processing /mnt/d/Alura/engenharia-dados-apache-airflow/datapipeline/airflow/dags/twitter_dag.py took 0.019 seconds
[2022-02-02 20:35:30,991] {scheduler_job.py:155} INFO - Started process (PID=7259) to work on /mnt/d/Alura/engenharia-dados-apache-airflow/datapipeline/airflow/dags/twitter_dag.py
[2022-02-02 20:35:30,993] {scheduler_job.py:1572} INFO - Processing file /mnt/d/Alura/engenharia-dados-apache-airflow/datapipeline/airflow/dags/twitter_dag.py for tasks to queue
[2022-02-02 20:35:30,994] {logging_mixin.py:112} INFO - [2022-02-02 20:35:30,994] {dagbag.py:417} INFO - Filling up the DagBag from /mnt/d/Alura/engenharia-dados-apache-airflow/datapipeline/airflow/dags/twitter_dag.py
[2022-02-02 20:35:30,997] {logging_mixin.py:112} INFO - [2022-02-02 20:35:30,996] {dagbag.py:259} ERROR - Failed to import: /mnt/d/Alura/engenharia-dados-apache-airflow/datapipeline/airflow/dags/twitter_dag.py
Traceback (most recent call last):
  File "/mnt/d/Alura/engenharia-dados-apache-airflow/datapipeline/.env/lib/python3.7/site-packages/airflow/models/dagbag.py", line 256, in process_file
    m = imp.load_source(mod_name, filepath)
  File "/home/felipe/anaconda3/lib/python3.7/imp.py", line 171, in load_source
    module = _load(spec)
  File "<frozen importlib._bootstrap>", line 696, in _load
  File "<frozen importlib._bootstrap>", line 677, in _load_unlocked
  File "<frozen importlib._bootstrap_external>", line 728, in exec_module
  File "<frozen importlib._bootstrap>", line 219, in _call_with_frames_removed
  File "/mnt/d/Alura/engenharia-dados-apache-airflow/datapipeline/airflow/dags/twitter_dag.py", line 4, in <module>
    from airflow.operators.alura import TwitterOperator
ModuleNotFoundError: No module named 'airflow.operators.alura'
[2022-02-02 20:35:30,997] {scheduler_job.py:1586} WARNING - No viable dags retrieved from /mnt/d/Alura/engenharia-dados-apache-airflow/datapipeline/airflow/dags/twitter_dag.py
[2022-02-02 20:35:31,008] {scheduler_job.py:163} INFO - Processing /mnt/d/Alura/engenharia-dados-apache-airflow/datapipeline/airflow/dags/twitter_dag.py took 0.017 seconds
[2022-02-02 20:36:23,035] {scheduler_job.py:155} INFO - Started process (PID=7296) to work on /mnt/d/Alura/engenharia-dados-apache-airflow/datapipeline/airflow/dags/twitter_dag.py
[2022-02-02 20:36:23,037] {scheduler_job.py:1572} INFO - Processing file /mnt/d/Alura/engenharia-dados-apache-airflow/datapipeline/airflow/dags/twitter_dag.py for tasks to queue
[2022-02-02 20:36:23,038] {logging_mixin.py:112} INFO - [2022-02-02 20:36:23,038] {dagbag.py:417} INFO - Filling up the DagBag from /mnt/d/Alura/engenharia-dados-apache-airflow/datapipeline/airflow/dags/twitter_dag.py
[2022-02-02 20:36:23,041] {logging_mixin.py:112} INFO - [2022-02-02 20:36:23,040] {dagbag.py:259} ERROR - Failed to import: /mnt/d/Alura/engenharia-dados-apache-airflow/datapipeline/airflow/dags/twitter_dag.py
Traceback (most recent call last):
  File "/mnt/d/Alura/engenharia-dados-apache-airflow/datapipeline/.env/lib/python3.7/site-packages/airflow/models/dagbag.py", line 256, in process_file
    m = imp.load_source(mod_name, filepath)
  File "/home/felipe/anaconda3/lib/python3.7/imp.py", line 171, in load_source
    module = _load(spec)
  File "<frozen importlib._bootstrap>", line 696, in _load
  File "<frozen importlib._bootstrap>", line 677, in _load_unlocked
  File "<frozen importlib._bootstrap_external>", line 728, in exec_module
  File "<frozen importlib._bootstrap>", line 219, in _call_with_frames_removed
  File "/mnt/d/Alura/engenharia-dados-apache-airflow/datapipeline/airflow/dags/twitter_dag.py", line 4, in <module>
    from airflow.operators.alura import TwitterOperator
ModuleNotFoundError: No module named 'airflow.operators.alura'
[2022-02-02 20:36:23,041] {scheduler_job.py:1586} WARNING - No viable dags retrieved from /mnt/d/Alura/engenharia-dados-apache-airflow/datapipeline/airflow/dags/twitter_dag.py
[2022-02-02 20:36:23,054] {scheduler_job.py:163} INFO - Processing /mnt/d/Alura/engenharia-dados-apache-airflow/datapipeline/airflow/dags/twitter_dag.py took 0.019 seconds
[2022-02-02 20:37:15,072] {scheduler_job.py:155} INFO - Started process (PID=7340) to work on /mnt/d/Alura/engenharia-dados-apache-airflow/datapipeline/airflow/dags/twitter_dag.py
[2022-02-02 20:37:15,074] {scheduler_job.py:1572} INFO - Processing file /mnt/d/Alura/engenharia-dados-apache-airflow/datapipeline/airflow/dags/twitter_dag.py for tasks to queue
[2022-02-02 20:37:15,075] {logging_mixin.py:112} INFO - [2022-02-02 20:37:15,075] {dagbag.py:417} INFO - Filling up the DagBag from /mnt/d/Alura/engenharia-dados-apache-airflow/datapipeline/airflow/dags/twitter_dag.py
[2022-02-02 20:37:15,078] {logging_mixin.py:112} INFO - [2022-02-02 20:37:15,077] {dagbag.py:259} ERROR - Failed to import: /mnt/d/Alura/engenharia-dados-apache-airflow/datapipeline/airflow/dags/twitter_dag.py
Traceback (most recent call last):
  File "/mnt/d/Alura/engenharia-dados-apache-airflow/datapipeline/.env/lib/python3.7/site-packages/airflow/models/dagbag.py", line 256, in process_file
    m = imp.load_source(mod_name, filepath)
  File "/home/felipe/anaconda3/lib/python3.7/imp.py", line 171, in load_source
    module = _load(spec)
  File "<frozen importlib._bootstrap>", line 696, in _load
  File "<frozen importlib._bootstrap>", line 677, in _load_unlocked
  File "<frozen importlib._bootstrap_external>", line 728, in exec_module
  File "<frozen importlib._bootstrap>", line 219, in _call_with_frames_removed
  File "/mnt/d/Alura/engenharia-dados-apache-airflow/datapipeline/airflow/dags/twitter_dag.py", line 4, in <module>
    from airflow.operators.alura import TwitterOperator
ModuleNotFoundError: No module named 'airflow.operators.alura'
[2022-02-02 20:37:15,078] {scheduler_job.py:1586} WARNING - No viable dags retrieved from /mnt/d/Alura/engenharia-dados-apache-airflow/datapipeline/airflow/dags/twitter_dag.py
[2022-02-02 20:37:15,090] {scheduler_job.py:163} INFO - Processing /mnt/d/Alura/engenharia-dados-apache-airflow/datapipeline/airflow/dags/twitter_dag.py took 0.018 seconds
[2022-02-02 20:38:07,103] {scheduler_job.py:155} INFO - Started process (PID=7385) to work on /mnt/d/Alura/engenharia-dados-apache-airflow/datapipeline/airflow/dags/twitter_dag.py
[2022-02-02 20:38:07,107] {scheduler_job.py:1572} INFO - Processing file /mnt/d/Alura/engenharia-dados-apache-airflow/datapipeline/airflow/dags/twitter_dag.py for tasks to queue
[2022-02-02 20:38:07,107] {logging_mixin.py:112} INFO - [2022-02-02 20:38:07,107] {dagbag.py:417} INFO - Filling up the DagBag from /mnt/d/Alura/engenharia-dados-apache-airflow/datapipeline/airflow/dags/twitter_dag.py
[2022-02-02 20:38:07,111] {logging_mixin.py:112} INFO - [2022-02-02 20:38:07,110] {dagbag.py:259} ERROR - Failed to import: /mnt/d/Alura/engenharia-dados-apache-airflow/datapipeline/airflow/dags/twitter_dag.py
Traceback (most recent call last):
  File "/mnt/d/Alura/engenharia-dados-apache-airflow/datapipeline/.env/lib/python3.7/site-packages/airflow/models/dagbag.py", line 256, in process_file
    m = imp.load_source(mod_name, filepath)
  File "/home/felipe/anaconda3/lib/python3.7/imp.py", line 171, in load_source
    module = _load(spec)
  File "<frozen importlib._bootstrap>", line 696, in _load
  File "<frozen importlib._bootstrap>", line 677, in _load_unlocked
  File "<frozen importlib._bootstrap_external>", line 728, in exec_module
  File "<frozen importlib._bootstrap>", line 219, in _call_with_frames_removed
  File "/mnt/d/Alura/engenharia-dados-apache-airflow/datapipeline/airflow/dags/twitter_dag.py", line 4, in <module>
    from airflow.operators.alura import TwitterOperator
ModuleNotFoundError: No module named 'airflow.operators.alura'
[2022-02-02 20:38:07,111] {scheduler_job.py:1586} WARNING - No viable dags retrieved from /mnt/d/Alura/engenharia-dados-apache-airflow/datapipeline/airflow/dags/twitter_dag.py
[2022-02-02 20:38:07,124] {scheduler_job.py:163} INFO - Processing /mnt/d/Alura/engenharia-dados-apache-airflow/datapipeline/airflow/dags/twitter_dag.py took 0.021 seconds
[2022-02-02 20:38:59,137] {scheduler_job.py:155} INFO - Started process (PID=7419) to work on /mnt/d/Alura/engenharia-dados-apache-airflow/datapipeline/airflow/dags/twitter_dag.py
[2022-02-02 20:38:59,140] {scheduler_job.py:1572} INFO - Processing file /mnt/d/Alura/engenharia-dados-apache-airflow/datapipeline/airflow/dags/twitter_dag.py for tasks to queue
[2022-02-02 20:38:59,141] {logging_mixin.py:112} INFO - [2022-02-02 20:38:59,141] {dagbag.py:417} INFO - Filling up the DagBag from /mnt/d/Alura/engenharia-dados-apache-airflow/datapipeline/airflow/dags/twitter_dag.py
[2022-02-02 20:38:59,145] {logging_mixin.py:112} INFO - [2022-02-02 20:38:59,143] {dagbag.py:259} ERROR - Failed to import: /mnt/d/Alura/engenharia-dados-apache-airflow/datapipeline/airflow/dags/twitter_dag.py
Traceback (most recent call last):
  File "/mnt/d/Alura/engenharia-dados-apache-airflow/datapipeline/.env/lib/python3.7/site-packages/airflow/models/dagbag.py", line 256, in process_file
    m = imp.load_source(mod_name, filepath)
  File "/home/felipe/anaconda3/lib/python3.7/imp.py", line 171, in load_source
    module = _load(spec)
  File "<frozen importlib._bootstrap>", line 696, in _load
  File "<frozen importlib._bootstrap>", line 677, in _load_unlocked
  File "<frozen importlib._bootstrap_external>", line 728, in exec_module
  File "<frozen importlib._bootstrap>", line 219, in _call_with_frames_removed
  File "/mnt/d/Alura/engenharia-dados-apache-airflow/datapipeline/airflow/dags/twitter_dag.py", line 4, in <module>
    from airflow.operators.alura import TwitterOperator
ModuleNotFoundError: No module named 'airflow.operators.alura'
[2022-02-02 20:38:59,145] {scheduler_job.py:1586} WARNING - No viable dags retrieved from /mnt/d/Alura/engenharia-dados-apache-airflow/datapipeline/airflow/dags/twitter_dag.py
[2022-02-02 20:38:59,157] {scheduler_job.py:163} INFO - Processing /mnt/d/Alura/engenharia-dados-apache-airflow/datapipeline/airflow/dags/twitter_dag.py took 0.020 seconds
[2022-02-02 20:39:51,241] {scheduler_job.py:155} INFO - Started process (PID=7464) to work on /mnt/d/Alura/engenharia-dados-apache-airflow/datapipeline/airflow/dags/twitter_dag.py
[2022-02-02 20:39:51,254] {scheduler_job.py:1572} INFO - Processing file /mnt/d/Alura/engenharia-dados-apache-airflow/datapipeline/airflow/dags/twitter_dag.py for tasks to queue
[2022-02-02 20:39:51,255] {logging_mixin.py:112} INFO - [2022-02-02 20:39:51,255] {dagbag.py:417} INFO - Filling up the DagBag from /mnt/d/Alura/engenharia-dados-apache-airflow/datapipeline/airflow/dags/twitter_dag.py
[2022-02-02 20:39:51,263] {logging_mixin.py:112} INFO - [2022-02-02 20:39:51,260] {dagbag.py:259} ERROR - Failed to import: /mnt/d/Alura/engenharia-dados-apache-airflow/datapipeline/airflow/dags/twitter_dag.py
Traceback (most recent call last):
  File "/mnt/d/Alura/engenharia-dados-apache-airflow/datapipeline/.env/lib/python3.7/site-packages/airflow/models/dagbag.py", line 256, in process_file
    m = imp.load_source(mod_name, filepath)
  File "/home/felipe/anaconda3/lib/python3.7/imp.py", line 171, in load_source
    module = _load(spec)
  File "<frozen importlib._bootstrap>", line 696, in _load
  File "<frozen importlib._bootstrap>", line 677, in _load_unlocked
  File "<frozen importlib._bootstrap_external>", line 728, in exec_module
  File "<frozen importlib._bootstrap>", line 219, in _call_with_frames_removed
  File "/mnt/d/Alura/engenharia-dados-apache-airflow/datapipeline/airflow/dags/twitter_dag.py", line 4, in <module>
    from airflow.operators.alura import TwitterOperator
ModuleNotFoundError: No module named 'airflow.operators.alura'
[2022-02-02 20:39:51,263] {scheduler_job.py:1586} WARNING - No viable dags retrieved from /mnt/d/Alura/engenharia-dados-apache-airflow/datapipeline/airflow/dags/twitter_dag.py
[2022-02-02 20:39:51,290] {scheduler_job.py:163} INFO - Processing /mnt/d/Alura/engenharia-dados-apache-airflow/datapipeline/airflow/dags/twitter_dag.py took 0.049 seconds
[2022-02-02 20:40:43,199] {scheduler_job.py:155} INFO - Started process (PID=7506) to work on /mnt/d/Alura/engenharia-dados-apache-airflow/datapipeline/airflow/dags/twitter_dag.py
[2022-02-02 20:40:43,202] {scheduler_job.py:1572} INFO - Processing file /mnt/d/Alura/engenharia-dados-apache-airflow/datapipeline/airflow/dags/twitter_dag.py for tasks to queue
[2022-02-02 20:40:43,204] {logging_mixin.py:112} INFO - [2022-02-02 20:40:43,204] {dagbag.py:417} INFO - Filling up the DagBag from /mnt/d/Alura/engenharia-dados-apache-airflow/datapipeline/airflow/dags/twitter_dag.py
[2022-02-02 20:40:43,208] {logging_mixin.py:112} INFO - [2022-02-02 20:40:43,207] {dagbag.py:259} ERROR - Failed to import: /mnt/d/Alura/engenharia-dados-apache-airflow/datapipeline/airflow/dags/twitter_dag.py
Traceback (most recent call last):
  File "/mnt/d/Alura/engenharia-dados-apache-airflow/datapipeline/.env/lib/python3.7/site-packages/airflow/models/dagbag.py", line 256, in process_file
    m = imp.load_source(mod_name, filepath)
  File "/home/felipe/anaconda3/lib/python3.7/imp.py", line 171, in load_source
    module = _load(spec)
  File "<frozen importlib._bootstrap>", line 696, in _load
  File "<frozen importlib._bootstrap>", line 677, in _load_unlocked
  File "<frozen importlib._bootstrap_external>", line 728, in exec_module
  File "<frozen importlib._bootstrap>", line 219, in _call_with_frames_removed
  File "/mnt/d/Alura/engenharia-dados-apache-airflow/datapipeline/airflow/dags/twitter_dag.py", line 4, in <module>
    from airflow.operators.alura import TwitterOperator
ModuleNotFoundError: No module named 'airflow.operators.alura'
[2022-02-02 20:40:43,208] {scheduler_job.py:1586} WARNING - No viable dags retrieved from /mnt/d/Alura/engenharia-dados-apache-airflow/datapipeline/airflow/dags/twitter_dag.py
[2022-02-02 20:40:43,220] {scheduler_job.py:163} INFO - Processing /mnt/d/Alura/engenharia-dados-apache-airflow/datapipeline/airflow/dags/twitter_dag.py took 0.021 seconds
[2022-02-02 20:41:35,241] {scheduler_job.py:155} INFO - Started process (PID=7548) to work on /mnt/d/Alura/engenharia-dados-apache-airflow/datapipeline/airflow/dags/twitter_dag.py
[2022-02-02 20:41:35,245] {scheduler_job.py:1572} INFO - Processing file /mnt/d/Alura/engenharia-dados-apache-airflow/datapipeline/airflow/dags/twitter_dag.py for tasks to queue
[2022-02-02 20:41:35,245] {logging_mixin.py:112} INFO - [2022-02-02 20:41:35,245] {dagbag.py:417} INFO - Filling up the DagBag from /mnt/d/Alura/engenharia-dados-apache-airflow/datapipeline/airflow/dags/twitter_dag.py
[2022-02-02 20:41:35,248] {logging_mixin.py:112} INFO - [2022-02-02 20:41:35,247] {dagbag.py:259} ERROR - Failed to import: /mnt/d/Alura/engenharia-dados-apache-airflow/datapipeline/airflow/dags/twitter_dag.py
Traceback (most recent call last):
  File "/mnt/d/Alura/engenharia-dados-apache-airflow/datapipeline/.env/lib/python3.7/site-packages/airflow/models/dagbag.py", line 256, in process_file
    m = imp.load_source(mod_name, filepath)
  File "/home/felipe/anaconda3/lib/python3.7/imp.py", line 171, in load_source
    module = _load(spec)
  File "<frozen importlib._bootstrap>", line 696, in _load
  File "<frozen importlib._bootstrap>", line 677, in _load_unlocked
  File "<frozen importlib._bootstrap_external>", line 728, in exec_module
  File "<frozen importlib._bootstrap>", line 219, in _call_with_frames_removed
  File "/mnt/d/Alura/engenharia-dados-apache-airflow/datapipeline/airflow/dags/twitter_dag.py", line 4, in <module>
    from airflow.operators.alura import TwitterOperator
ModuleNotFoundError: No module named 'airflow.operators.alura'
[2022-02-02 20:41:35,248] {scheduler_job.py:1586} WARNING - No viable dags retrieved from /mnt/d/Alura/engenharia-dados-apache-airflow/datapipeline/airflow/dags/twitter_dag.py
[2022-02-02 20:41:35,260] {scheduler_job.py:163} INFO - Processing /mnt/d/Alura/engenharia-dados-apache-airflow/datapipeline/airflow/dags/twitter_dag.py took 0.019 seconds
[2022-02-02 20:42:27,266] {scheduler_job.py:155} INFO - Started process (PID=7582) to work on /mnt/d/Alura/engenharia-dados-apache-airflow/datapipeline/airflow/dags/twitter_dag.py
[2022-02-02 20:42:27,269] {scheduler_job.py:1572} INFO - Processing file /mnt/d/Alura/engenharia-dados-apache-airflow/datapipeline/airflow/dags/twitter_dag.py for tasks to queue
[2022-02-02 20:42:27,269] {logging_mixin.py:112} INFO - [2022-02-02 20:42:27,269] {dagbag.py:417} INFO - Filling up the DagBag from /mnt/d/Alura/engenharia-dados-apache-airflow/datapipeline/airflow/dags/twitter_dag.py
[2022-02-02 20:42:27,272] {logging_mixin.py:112} INFO - [2022-02-02 20:42:27,271] {dagbag.py:259} ERROR - Failed to import: /mnt/d/Alura/engenharia-dados-apache-airflow/datapipeline/airflow/dags/twitter_dag.py
Traceback (most recent call last):
  File "/mnt/d/Alura/engenharia-dados-apache-airflow/datapipeline/.env/lib/python3.7/site-packages/airflow/models/dagbag.py", line 256, in process_file
    m = imp.load_source(mod_name, filepath)
  File "/home/felipe/anaconda3/lib/python3.7/imp.py", line 171, in load_source
    module = _load(spec)
  File "<frozen importlib._bootstrap>", line 696, in _load
  File "<frozen importlib._bootstrap>", line 677, in _load_unlocked
  File "<frozen importlib._bootstrap_external>", line 728, in exec_module
  File "<frozen importlib._bootstrap>", line 219, in _call_with_frames_removed
  File "/mnt/d/Alura/engenharia-dados-apache-airflow/datapipeline/airflow/dags/twitter_dag.py", line 4, in <module>
    from airflow.operators.alura import TwitterOperator
ModuleNotFoundError: No module named 'airflow.operators.alura'
[2022-02-02 20:42:27,272] {scheduler_job.py:1586} WARNING - No viable dags retrieved from /mnt/d/Alura/engenharia-dados-apache-airflow/datapipeline/airflow/dags/twitter_dag.py
[2022-02-02 20:42:27,283] {scheduler_job.py:163} INFO - Processing /mnt/d/Alura/engenharia-dados-apache-airflow/datapipeline/airflow/dags/twitter_dag.py took 0.017 seconds
[2022-02-02 20:43:19,296] {scheduler_job.py:155} INFO - Started process (PID=7624) to work on /mnt/d/Alura/engenharia-dados-apache-airflow/datapipeline/airflow/dags/twitter_dag.py
[2022-02-02 20:43:19,299] {scheduler_job.py:1572} INFO - Processing file /mnt/d/Alura/engenharia-dados-apache-airflow/datapipeline/airflow/dags/twitter_dag.py for tasks to queue
[2022-02-02 20:43:19,299] {logging_mixin.py:112} INFO - [2022-02-02 20:43:19,299] {dagbag.py:417} INFO - Filling up the DagBag from /mnt/d/Alura/engenharia-dados-apache-airflow/datapipeline/airflow/dags/twitter_dag.py
[2022-02-02 20:43:19,302] {logging_mixin.py:112} INFO - [2022-02-02 20:43:19,301] {dagbag.py:259} ERROR - Failed to import: /mnt/d/Alura/engenharia-dados-apache-airflow/datapipeline/airflow/dags/twitter_dag.py
Traceback (most recent call last):
  File "/mnt/d/Alura/engenharia-dados-apache-airflow/datapipeline/.env/lib/python3.7/site-packages/airflow/models/dagbag.py", line 256, in process_file
    m = imp.load_source(mod_name, filepath)
  File "/home/felipe/anaconda3/lib/python3.7/imp.py", line 171, in load_source
    module = _load(spec)
  File "<frozen importlib._bootstrap>", line 696, in _load
  File "<frozen importlib._bootstrap>", line 677, in _load_unlocked
  File "<frozen importlib._bootstrap_external>", line 728, in exec_module
  File "<frozen importlib._bootstrap>", line 219, in _call_with_frames_removed
  File "/mnt/d/Alura/engenharia-dados-apache-airflow/datapipeline/airflow/dags/twitter_dag.py", line 4, in <module>
    from airflow.operators.alura import TwitterOperator
ModuleNotFoundError: No module named 'airflow.operators.alura'
[2022-02-02 20:43:19,303] {scheduler_job.py:1586} WARNING - No viable dags retrieved from /mnt/d/Alura/engenharia-dados-apache-airflow/datapipeline/airflow/dags/twitter_dag.py
[2022-02-02 20:43:19,315] {scheduler_job.py:163} INFO - Processing /mnt/d/Alura/engenharia-dados-apache-airflow/datapipeline/airflow/dags/twitter_dag.py took 0.019 seconds
[2022-02-02 20:44:11,327] {scheduler_job.py:155} INFO - Started process (PID=7666) to work on /mnt/d/Alura/engenharia-dados-apache-airflow/datapipeline/airflow/dags/twitter_dag.py
[2022-02-02 20:44:11,330] {scheduler_job.py:1572} INFO - Processing file /mnt/d/Alura/engenharia-dados-apache-airflow/datapipeline/airflow/dags/twitter_dag.py for tasks to queue
[2022-02-02 20:44:11,330] {logging_mixin.py:112} INFO - [2022-02-02 20:44:11,330] {dagbag.py:417} INFO - Filling up the DagBag from /mnt/d/Alura/engenharia-dados-apache-airflow/datapipeline/airflow/dags/twitter_dag.py
[2022-02-02 20:44:11,333] {logging_mixin.py:112} INFO - [2022-02-02 20:44:11,332] {dagbag.py:259} ERROR - Failed to import: /mnt/d/Alura/engenharia-dados-apache-airflow/datapipeline/airflow/dags/twitter_dag.py
Traceback (most recent call last):
  File "/mnt/d/Alura/engenharia-dados-apache-airflow/datapipeline/.env/lib/python3.7/site-packages/airflow/models/dagbag.py", line 256, in process_file
    m = imp.load_source(mod_name, filepath)
  File "/home/felipe/anaconda3/lib/python3.7/imp.py", line 171, in load_source
    module = _load(spec)
  File "<frozen importlib._bootstrap>", line 696, in _load
  File "<frozen importlib._bootstrap>", line 677, in _load_unlocked
  File "<frozen importlib._bootstrap_external>", line 728, in exec_module
  File "<frozen importlib._bootstrap>", line 219, in _call_with_frames_removed
  File "/mnt/d/Alura/engenharia-dados-apache-airflow/datapipeline/airflow/dags/twitter_dag.py", line 4, in <module>
    from airflow.operators.alura import TwitterOperator
ModuleNotFoundError: No module named 'airflow.operators.alura'
[2022-02-02 20:44:11,333] {scheduler_job.py:1586} WARNING - No viable dags retrieved from /mnt/d/Alura/engenharia-dados-apache-airflow/datapipeline/airflow/dags/twitter_dag.py
[2022-02-02 20:44:11,345] {scheduler_job.py:163} INFO - Processing /mnt/d/Alura/engenharia-dados-apache-airflow/datapipeline/airflow/dags/twitter_dag.py took 0.019 seconds
[2022-02-02 20:45:03,358] {scheduler_job.py:155} INFO - Started process (PID=7700) to work on /mnt/d/Alura/engenharia-dados-apache-airflow/datapipeline/airflow/dags/twitter_dag.py
[2022-02-02 20:45:03,361] {scheduler_job.py:1572} INFO - Processing file /mnt/d/Alura/engenharia-dados-apache-airflow/datapipeline/airflow/dags/twitter_dag.py for tasks to queue
[2022-02-02 20:45:03,361] {logging_mixin.py:112} INFO - [2022-02-02 20:45:03,361] {dagbag.py:417} INFO - Filling up the DagBag from /mnt/d/Alura/engenharia-dados-apache-airflow/datapipeline/airflow/dags/twitter_dag.py
[2022-02-02 20:45:03,364] {logging_mixin.py:112} INFO - [2022-02-02 20:45:03,363] {dagbag.py:259} ERROR - Failed to import: /mnt/d/Alura/engenharia-dados-apache-airflow/datapipeline/airflow/dags/twitter_dag.py
Traceback (most recent call last):
  File "/mnt/d/Alura/engenharia-dados-apache-airflow/datapipeline/.env/lib/python3.7/site-packages/airflow/models/dagbag.py", line 256, in process_file
    m = imp.load_source(mod_name, filepath)
  File "/home/felipe/anaconda3/lib/python3.7/imp.py", line 171, in load_source
    module = _load(spec)
  File "<frozen importlib._bootstrap>", line 696, in _load
  File "<frozen importlib._bootstrap>", line 677, in _load_unlocked
  File "<frozen importlib._bootstrap_external>", line 728, in exec_module
  File "<frozen importlib._bootstrap>", line 219, in _call_with_frames_removed
  File "/mnt/d/Alura/engenharia-dados-apache-airflow/datapipeline/airflow/dags/twitter_dag.py", line 4, in <module>
    from airflow.operators.alura import TwitterOperator
ModuleNotFoundError: No module named 'airflow.operators.alura'
[2022-02-02 20:45:03,364] {scheduler_job.py:1586} WARNING - No viable dags retrieved from /mnt/d/Alura/engenharia-dados-apache-airflow/datapipeline/airflow/dags/twitter_dag.py
[2022-02-02 20:45:03,374] {scheduler_job.py:163} INFO - Processing /mnt/d/Alura/engenharia-dados-apache-airflow/datapipeline/airflow/dags/twitter_dag.py took 0.016 seconds
[2022-02-02 20:45:55,388] {scheduler_job.py:155} INFO - Started process (PID=7742) to work on /mnt/d/Alura/engenharia-dados-apache-airflow/datapipeline/airflow/dags/twitter_dag.py
[2022-02-02 20:45:55,391] {scheduler_job.py:1572} INFO - Processing file /mnt/d/Alura/engenharia-dados-apache-airflow/datapipeline/airflow/dags/twitter_dag.py for tasks to queue
[2022-02-02 20:45:55,391] {logging_mixin.py:112} INFO - [2022-02-02 20:45:55,391] {dagbag.py:417} INFO - Filling up the DagBag from /mnt/d/Alura/engenharia-dados-apache-airflow/datapipeline/airflow/dags/twitter_dag.py
[2022-02-02 20:45:55,394] {logging_mixin.py:112} INFO - [2022-02-02 20:45:55,393] {dagbag.py:259} ERROR - Failed to import: /mnt/d/Alura/engenharia-dados-apache-airflow/datapipeline/airflow/dags/twitter_dag.py
Traceback (most recent call last):
  File "/mnt/d/Alura/engenharia-dados-apache-airflow/datapipeline/.env/lib/python3.7/site-packages/airflow/models/dagbag.py", line 256, in process_file
    m = imp.load_source(mod_name, filepath)
  File "/home/felipe/anaconda3/lib/python3.7/imp.py", line 171, in load_source
    module = _load(spec)
  File "<frozen importlib._bootstrap>", line 696, in _load
  File "<frozen importlib._bootstrap>", line 677, in _load_unlocked
  File "<frozen importlib._bootstrap_external>", line 728, in exec_module
  File "<frozen importlib._bootstrap>", line 219, in _call_with_frames_removed
  File "/mnt/d/Alura/engenharia-dados-apache-airflow/datapipeline/airflow/dags/twitter_dag.py", line 4, in <module>
    from airflow.operators.alura import TwitterOperator
ModuleNotFoundError: No module named 'airflow.operators.alura'
[2022-02-02 20:45:55,394] {scheduler_job.py:1586} WARNING - No viable dags retrieved from /mnt/d/Alura/engenharia-dados-apache-airflow/datapipeline/airflow/dags/twitter_dag.py
[2022-02-02 20:45:55,405] {scheduler_job.py:163} INFO - Processing /mnt/d/Alura/engenharia-dados-apache-airflow/datapipeline/airflow/dags/twitter_dag.py took 0.017 seconds
[2022-02-02 20:46:47,413] {scheduler_job.py:155} INFO - Started process (PID=7784) to work on /mnt/d/Alura/engenharia-dados-apache-airflow/datapipeline/airflow/dags/twitter_dag.py
[2022-02-02 20:46:47,416] {scheduler_job.py:1572} INFO - Processing file /mnt/d/Alura/engenharia-dados-apache-airflow/datapipeline/airflow/dags/twitter_dag.py for tasks to queue
[2022-02-02 20:46:47,416] {logging_mixin.py:112} INFO - [2022-02-02 20:46:47,416] {dagbag.py:417} INFO - Filling up the DagBag from /mnt/d/Alura/engenharia-dados-apache-airflow/datapipeline/airflow/dags/twitter_dag.py
[2022-02-02 20:46:47,419] {logging_mixin.py:112} INFO - [2022-02-02 20:46:47,418] {dagbag.py:259} ERROR - Failed to import: /mnt/d/Alura/engenharia-dados-apache-airflow/datapipeline/airflow/dags/twitter_dag.py
Traceback (most recent call last):
  File "/mnt/d/Alura/engenharia-dados-apache-airflow/datapipeline/.env/lib/python3.7/site-packages/airflow/models/dagbag.py", line 256, in process_file
    m = imp.load_source(mod_name, filepath)
  File "/home/felipe/anaconda3/lib/python3.7/imp.py", line 171, in load_source
    module = _load(spec)
  File "<frozen importlib._bootstrap>", line 696, in _load
  File "<frozen importlib._bootstrap>", line 677, in _load_unlocked
  File "<frozen importlib._bootstrap_external>", line 728, in exec_module
  File "<frozen importlib._bootstrap>", line 219, in _call_with_frames_removed
  File "/mnt/d/Alura/engenharia-dados-apache-airflow/datapipeline/airflow/dags/twitter_dag.py", line 4, in <module>
    from airflow.operators.alura import TwitterOperator
ModuleNotFoundError: No module named 'airflow.operators.alura'
[2022-02-02 20:46:47,419] {scheduler_job.py:1586} WARNING - No viable dags retrieved from /mnt/d/Alura/engenharia-dados-apache-airflow/datapipeline/airflow/dags/twitter_dag.py
[2022-02-02 20:46:47,430] {scheduler_job.py:163} INFO - Processing /mnt/d/Alura/engenharia-dados-apache-airflow/datapipeline/airflow/dags/twitter_dag.py took 0.017 seconds
[2022-02-02 20:47:39,448] {scheduler_job.py:155} INFO - Started process (PID=7826) to work on /mnt/d/Alura/engenharia-dados-apache-airflow/datapipeline/airflow/dags/twitter_dag.py
[2022-02-02 20:47:39,450] {scheduler_job.py:1572} INFO - Processing file /mnt/d/Alura/engenharia-dados-apache-airflow/datapipeline/airflow/dags/twitter_dag.py for tasks to queue
[2022-02-02 20:47:39,450] {logging_mixin.py:112} INFO - [2022-02-02 20:47:39,450] {dagbag.py:417} INFO - Filling up the DagBag from /mnt/d/Alura/engenharia-dados-apache-airflow/datapipeline/airflow/dags/twitter_dag.py
[2022-02-02 20:47:39,453] {logging_mixin.py:112} INFO - [2022-02-02 20:47:39,452] {dagbag.py:259} ERROR - Failed to import: /mnt/d/Alura/engenharia-dados-apache-airflow/datapipeline/airflow/dags/twitter_dag.py
Traceback (most recent call last):
  File "/mnt/d/Alura/engenharia-dados-apache-airflow/datapipeline/.env/lib/python3.7/site-packages/airflow/models/dagbag.py", line 256, in process_file
    m = imp.load_source(mod_name, filepath)
  File "/home/felipe/anaconda3/lib/python3.7/imp.py", line 171, in load_source
    module = _load(spec)
  File "<frozen importlib._bootstrap>", line 696, in _load
  File "<frozen importlib._bootstrap>", line 677, in _load_unlocked
  File "<frozen importlib._bootstrap_external>", line 728, in exec_module
  File "<frozen importlib._bootstrap>", line 219, in _call_with_frames_removed
  File "/mnt/d/Alura/engenharia-dados-apache-airflow/datapipeline/airflow/dags/twitter_dag.py", line 4, in <module>
    from airflow.operators.alura import TwitterOperator
ModuleNotFoundError: No module named 'airflow.operators.alura'
[2022-02-02 20:47:39,453] {scheduler_job.py:1586} WARNING - No viable dags retrieved from /mnt/d/Alura/engenharia-dados-apache-airflow/datapipeline/airflow/dags/twitter_dag.py
[2022-02-02 20:47:39,464] {scheduler_job.py:163} INFO - Processing /mnt/d/Alura/engenharia-dados-apache-airflow/datapipeline/airflow/dags/twitter_dag.py took 0.016 seconds
[2022-02-02 20:48:31,476] {scheduler_job.py:155} INFO - Started process (PID=7860) to work on /mnt/d/Alura/engenharia-dados-apache-airflow/datapipeline/airflow/dags/twitter_dag.py
[2022-02-02 20:48:31,478] {scheduler_job.py:1572} INFO - Processing file /mnt/d/Alura/engenharia-dados-apache-airflow/datapipeline/airflow/dags/twitter_dag.py for tasks to queue
[2022-02-02 20:48:31,479] {logging_mixin.py:112} INFO - [2022-02-02 20:48:31,479] {dagbag.py:417} INFO - Filling up the DagBag from /mnt/d/Alura/engenharia-dados-apache-airflow/datapipeline/airflow/dags/twitter_dag.py
[2022-02-02 20:48:31,482] {logging_mixin.py:112} INFO - [2022-02-02 20:48:31,481] {dagbag.py:259} ERROR - Failed to import: /mnt/d/Alura/engenharia-dados-apache-airflow/datapipeline/airflow/dags/twitter_dag.py
Traceback (most recent call last):
  File "/mnt/d/Alura/engenharia-dados-apache-airflow/datapipeline/.env/lib/python3.7/site-packages/airflow/models/dagbag.py", line 256, in process_file
    m = imp.load_source(mod_name, filepath)
  File "/home/felipe/anaconda3/lib/python3.7/imp.py", line 171, in load_source
    module = _load(spec)
  File "<frozen importlib._bootstrap>", line 696, in _load
  File "<frozen importlib._bootstrap>", line 677, in _load_unlocked
  File "<frozen importlib._bootstrap_external>", line 728, in exec_module
  File "<frozen importlib._bootstrap>", line 219, in _call_with_frames_removed
  File "/mnt/d/Alura/engenharia-dados-apache-airflow/datapipeline/airflow/dags/twitter_dag.py", line 4, in <module>
    from airflow.operators.alura import TwitterOperator
ModuleNotFoundError: No module named 'airflow.operators.alura'
[2022-02-02 20:48:31,482] {scheduler_job.py:1586} WARNING - No viable dags retrieved from /mnt/d/Alura/engenharia-dados-apache-airflow/datapipeline/airflow/dags/twitter_dag.py
[2022-02-02 20:48:31,493] {scheduler_job.py:163} INFO - Processing /mnt/d/Alura/engenharia-dados-apache-airflow/datapipeline/airflow/dags/twitter_dag.py took 0.017 seconds
[2022-02-02 20:49:23,505] {scheduler_job.py:155} INFO - Started process (PID=7902) to work on /mnt/d/Alura/engenharia-dados-apache-airflow/datapipeline/airflow/dags/twitter_dag.py
[2022-02-02 20:49:23,508] {scheduler_job.py:1572} INFO - Processing file /mnt/d/Alura/engenharia-dados-apache-airflow/datapipeline/airflow/dags/twitter_dag.py for tasks to queue
[2022-02-02 20:49:23,508] {logging_mixin.py:112} INFO - [2022-02-02 20:49:23,508] {dagbag.py:417} INFO - Filling up the DagBag from /mnt/d/Alura/engenharia-dados-apache-airflow/datapipeline/airflow/dags/twitter_dag.py
[2022-02-02 20:49:23,511] {logging_mixin.py:112} INFO - [2022-02-02 20:49:23,510] {dagbag.py:259} ERROR - Failed to import: /mnt/d/Alura/engenharia-dados-apache-airflow/datapipeline/airflow/dags/twitter_dag.py
Traceback (most recent call last):
  File "/mnt/d/Alura/engenharia-dados-apache-airflow/datapipeline/.env/lib/python3.7/site-packages/airflow/models/dagbag.py", line 256, in process_file
    m = imp.load_source(mod_name, filepath)
  File "/home/felipe/anaconda3/lib/python3.7/imp.py", line 171, in load_source
    module = _load(spec)
  File "<frozen importlib._bootstrap>", line 696, in _load
  File "<frozen importlib._bootstrap>", line 677, in _load_unlocked
  File "<frozen importlib._bootstrap_external>", line 728, in exec_module
  File "<frozen importlib._bootstrap>", line 219, in _call_with_frames_removed
  File "/mnt/d/Alura/engenharia-dados-apache-airflow/datapipeline/airflow/dags/twitter_dag.py", line 4, in <module>
    from airflow.operators.alura import TwitterOperator
ModuleNotFoundError: No module named 'airflow.operators.alura'
[2022-02-02 20:49:23,511] {scheduler_job.py:1586} WARNING - No viable dags retrieved from /mnt/d/Alura/engenharia-dados-apache-airflow/datapipeline/airflow/dags/twitter_dag.py
[2022-02-02 20:49:23,522] {scheduler_job.py:163} INFO - Processing /mnt/d/Alura/engenharia-dados-apache-airflow/datapipeline/airflow/dags/twitter_dag.py took 0.017 seconds
[2022-02-02 20:50:15,532] {scheduler_job.py:155} INFO - Started process (PID=7944) to work on /mnt/d/Alura/engenharia-dados-apache-airflow/datapipeline/airflow/dags/twitter_dag.py
[2022-02-02 20:50:15,535] {scheduler_job.py:1572} INFO - Processing file /mnt/d/Alura/engenharia-dados-apache-airflow/datapipeline/airflow/dags/twitter_dag.py for tasks to queue
[2022-02-02 20:50:15,536] {logging_mixin.py:112} INFO - [2022-02-02 20:50:15,535] {dagbag.py:417} INFO - Filling up the DagBag from /mnt/d/Alura/engenharia-dados-apache-airflow/datapipeline/airflow/dags/twitter_dag.py
[2022-02-02 20:50:15,539] {logging_mixin.py:112} INFO - [2022-02-02 20:50:15,537] {dagbag.py:259} ERROR - Failed to import: /mnt/d/Alura/engenharia-dados-apache-airflow/datapipeline/airflow/dags/twitter_dag.py
Traceback (most recent call last):
  File "/mnt/d/Alura/engenharia-dados-apache-airflow/datapipeline/.env/lib/python3.7/site-packages/airflow/models/dagbag.py", line 256, in process_file
    m = imp.load_source(mod_name, filepath)
  File "/home/felipe/anaconda3/lib/python3.7/imp.py", line 171, in load_source
    module = _load(spec)
  File "<frozen importlib._bootstrap>", line 696, in _load
  File "<frozen importlib._bootstrap>", line 677, in _load_unlocked
  File "<frozen importlib._bootstrap_external>", line 728, in exec_module
  File "<frozen importlib._bootstrap>", line 219, in _call_with_frames_removed
  File "/mnt/d/Alura/engenharia-dados-apache-airflow/datapipeline/airflow/dags/twitter_dag.py", line 4, in <module>
    from airflow.operators.alura import TwitterOperator
ModuleNotFoundError: No module named 'airflow.operators.alura'
[2022-02-02 20:50:15,539] {scheduler_job.py:1586} WARNING - No viable dags retrieved from /mnt/d/Alura/engenharia-dados-apache-airflow/datapipeline/airflow/dags/twitter_dag.py
[2022-02-02 20:50:15,549] {scheduler_job.py:163} INFO - Processing /mnt/d/Alura/engenharia-dados-apache-airflow/datapipeline/airflow/dags/twitter_dag.py took 0.016 seconds
[2022-02-02 20:51:07,561] {scheduler_job.py:155} INFO - Started process (PID=7978) to work on /mnt/d/Alura/engenharia-dados-apache-airflow/datapipeline/airflow/dags/twitter_dag.py
[2022-02-02 20:51:07,564] {scheduler_job.py:1572} INFO - Processing file /mnt/d/Alura/engenharia-dados-apache-airflow/datapipeline/airflow/dags/twitter_dag.py for tasks to queue
[2022-02-02 20:51:07,564] {logging_mixin.py:112} INFO - [2022-02-02 20:51:07,564] {dagbag.py:417} INFO - Filling up the DagBag from /mnt/d/Alura/engenharia-dados-apache-airflow/datapipeline/airflow/dags/twitter_dag.py
[2022-02-02 20:51:07,567] {logging_mixin.py:112} INFO - [2022-02-02 20:51:07,566] {dagbag.py:259} ERROR - Failed to import: /mnt/d/Alura/engenharia-dados-apache-airflow/datapipeline/airflow/dags/twitter_dag.py
Traceback (most recent call last):
  File "/mnt/d/Alura/engenharia-dados-apache-airflow/datapipeline/.env/lib/python3.7/site-packages/airflow/models/dagbag.py", line 256, in process_file
    m = imp.load_source(mod_name, filepath)
  File "/home/felipe/anaconda3/lib/python3.7/imp.py", line 171, in load_source
    module = _load(spec)
  File "<frozen importlib._bootstrap>", line 696, in _load
  File "<frozen importlib._bootstrap>", line 677, in _load_unlocked
  File "<frozen importlib._bootstrap_external>", line 728, in exec_module
  File "<frozen importlib._bootstrap>", line 219, in _call_with_frames_removed
  File "/mnt/d/Alura/engenharia-dados-apache-airflow/datapipeline/airflow/dags/twitter_dag.py", line 4, in <module>
    from airflow.operators.alura import TwitterOperator
ModuleNotFoundError: No module named 'airflow.operators.alura'
[2022-02-02 20:51:07,567] {scheduler_job.py:1586} WARNING - No viable dags retrieved from /mnt/d/Alura/engenharia-dados-apache-airflow/datapipeline/airflow/dags/twitter_dag.py
[2022-02-02 20:51:07,578] {scheduler_job.py:163} INFO - Processing /mnt/d/Alura/engenharia-dados-apache-airflow/datapipeline/airflow/dags/twitter_dag.py took 0.016 seconds
[2022-02-02 20:51:59,592] {scheduler_job.py:155} INFO - Started process (PID=8020) to work on /mnt/d/Alura/engenharia-dados-apache-airflow/datapipeline/airflow/dags/twitter_dag.py
[2022-02-02 20:51:59,595] {scheduler_job.py:1572} INFO - Processing file /mnt/d/Alura/engenharia-dados-apache-airflow/datapipeline/airflow/dags/twitter_dag.py for tasks to queue
[2022-02-02 20:51:59,595] {logging_mixin.py:112} INFO - [2022-02-02 20:51:59,595] {dagbag.py:417} INFO - Filling up the DagBag from /mnt/d/Alura/engenharia-dados-apache-airflow/datapipeline/airflow/dags/twitter_dag.py
[2022-02-02 20:51:59,598] {logging_mixin.py:112} INFO - [2022-02-02 20:51:59,597] {dagbag.py:259} ERROR - Failed to import: /mnt/d/Alura/engenharia-dados-apache-airflow/datapipeline/airflow/dags/twitter_dag.py
Traceback (most recent call last):
  File "/mnt/d/Alura/engenharia-dados-apache-airflow/datapipeline/.env/lib/python3.7/site-packages/airflow/models/dagbag.py", line 256, in process_file
    m = imp.load_source(mod_name, filepath)
  File "/home/felipe/anaconda3/lib/python3.7/imp.py", line 171, in load_source
    module = _load(spec)
  File "<frozen importlib._bootstrap>", line 696, in _load
  File "<frozen importlib._bootstrap>", line 677, in _load_unlocked
  File "<frozen importlib._bootstrap_external>", line 728, in exec_module
  File "<frozen importlib._bootstrap>", line 219, in _call_with_frames_removed
  File "/mnt/d/Alura/engenharia-dados-apache-airflow/datapipeline/airflow/dags/twitter_dag.py", line 4, in <module>
    from airflow.operators.alura import TwitterOperator
ModuleNotFoundError: No module named 'airflow.operators.alura'
[2022-02-02 20:51:59,598] {scheduler_job.py:1586} WARNING - No viable dags retrieved from /mnt/d/Alura/engenharia-dados-apache-airflow/datapipeline/airflow/dags/twitter_dag.py
[2022-02-02 20:51:59,609] {scheduler_job.py:163} INFO - Processing /mnt/d/Alura/engenharia-dados-apache-airflow/datapipeline/airflow/dags/twitter_dag.py took 0.017 seconds
[2022-02-02 20:52:51,617] {scheduler_job.py:155} INFO - Started process (PID=8062) to work on /mnt/d/Alura/engenharia-dados-apache-airflow/datapipeline/airflow/dags/twitter_dag.py
[2022-02-02 20:52:51,619] {scheduler_job.py:1572} INFO - Processing file /mnt/d/Alura/engenharia-dados-apache-airflow/datapipeline/airflow/dags/twitter_dag.py for tasks to queue
[2022-02-02 20:52:51,620] {logging_mixin.py:112} INFO - [2022-02-02 20:52:51,620] {dagbag.py:417} INFO - Filling up the DagBag from /mnt/d/Alura/engenharia-dados-apache-airflow/datapipeline/airflow/dags/twitter_dag.py
[2022-02-02 20:52:51,622] {logging_mixin.py:112} INFO - [2022-02-02 20:52:51,622] {dagbag.py:259} ERROR - Failed to import: /mnt/d/Alura/engenharia-dados-apache-airflow/datapipeline/airflow/dags/twitter_dag.py
Traceback (most recent call last):
  File "/mnt/d/Alura/engenharia-dados-apache-airflow/datapipeline/.env/lib/python3.7/site-packages/airflow/models/dagbag.py", line 256, in process_file
    m = imp.load_source(mod_name, filepath)
  File "/home/felipe/anaconda3/lib/python3.7/imp.py", line 171, in load_source
    module = _load(spec)
  File "<frozen importlib._bootstrap>", line 696, in _load
  File "<frozen importlib._bootstrap>", line 677, in _load_unlocked
  File "<frozen importlib._bootstrap_external>", line 728, in exec_module
  File "<frozen importlib._bootstrap>", line 219, in _call_with_frames_removed
  File "/mnt/d/Alura/engenharia-dados-apache-airflow/datapipeline/airflow/dags/twitter_dag.py", line 4, in <module>
    from airflow.operators.alura import TwitterOperator
ModuleNotFoundError: No module named 'airflow.operators.alura'
[2022-02-02 20:52:51,623] {scheduler_job.py:1586} WARNING - No viable dags retrieved from /mnt/d/Alura/engenharia-dados-apache-airflow/datapipeline/airflow/dags/twitter_dag.py
[2022-02-02 20:52:51,633] {scheduler_job.py:163} INFO - Processing /mnt/d/Alura/engenharia-dados-apache-airflow/datapipeline/airflow/dags/twitter_dag.py took 0.016 seconds
[2022-02-02 20:53:43,637] {scheduler_job.py:155} INFO - Started process (PID=8104) to work on /mnt/d/Alura/engenharia-dados-apache-airflow/datapipeline/airflow/dags/twitter_dag.py
[2022-02-02 20:53:43,639] {scheduler_job.py:1572} INFO - Processing file /mnt/d/Alura/engenharia-dados-apache-airflow/datapipeline/airflow/dags/twitter_dag.py for tasks to queue
[2022-02-02 20:53:43,639] {logging_mixin.py:112} INFO - [2022-02-02 20:53:43,639] {dagbag.py:417} INFO - Filling up the DagBag from /mnt/d/Alura/engenharia-dados-apache-airflow/datapipeline/airflow/dags/twitter_dag.py
[2022-02-02 20:53:43,642] {logging_mixin.py:112} INFO - [2022-02-02 20:53:43,641] {dagbag.py:259} ERROR - Failed to import: /mnt/d/Alura/engenharia-dados-apache-airflow/datapipeline/airflow/dags/twitter_dag.py
Traceback (most recent call last):
  File "/mnt/d/Alura/engenharia-dados-apache-airflow/datapipeline/.env/lib/python3.7/site-packages/airflow/models/dagbag.py", line 256, in process_file
    m = imp.load_source(mod_name, filepath)
  File "/home/felipe/anaconda3/lib/python3.7/imp.py", line 171, in load_source
    module = _load(spec)
  File "<frozen importlib._bootstrap>", line 696, in _load
  File "<frozen importlib._bootstrap>", line 677, in _load_unlocked
  File "<frozen importlib._bootstrap_external>", line 728, in exec_module
  File "<frozen importlib._bootstrap>", line 219, in _call_with_frames_removed
  File "/mnt/d/Alura/engenharia-dados-apache-airflow/datapipeline/airflow/dags/twitter_dag.py", line 4, in <module>
    from airflow.operators.alura import TwitterOperator
ModuleNotFoundError: No module named 'airflow.operators.alura'
[2022-02-02 20:53:43,642] {scheduler_job.py:1586} WARNING - No viable dags retrieved from /mnt/d/Alura/engenharia-dados-apache-airflow/datapipeline/airflow/dags/twitter_dag.py
[2022-02-02 20:53:43,654] {scheduler_job.py:163} INFO - Processing /mnt/d/Alura/engenharia-dados-apache-airflow/datapipeline/airflow/dags/twitter_dag.py took 0.017 seconds
[2022-02-02 20:54:35,656] {scheduler_job.py:155} INFO - Started process (PID=8138) to work on /mnt/d/Alura/engenharia-dados-apache-airflow/datapipeline/airflow/dags/twitter_dag.py
[2022-02-02 20:54:35,659] {scheduler_job.py:1572} INFO - Processing file /mnt/d/Alura/engenharia-dados-apache-airflow/datapipeline/airflow/dags/twitter_dag.py for tasks to queue
[2022-02-02 20:54:35,659] {logging_mixin.py:112} INFO - [2022-02-02 20:54:35,659] {dagbag.py:417} INFO - Filling up the DagBag from /mnt/d/Alura/engenharia-dados-apache-airflow/datapipeline/airflow/dags/twitter_dag.py
[2022-02-02 20:54:35,662] {logging_mixin.py:112} INFO - [2022-02-02 20:54:35,661] {dagbag.py:259} ERROR - Failed to import: /mnt/d/Alura/engenharia-dados-apache-airflow/datapipeline/airflow/dags/twitter_dag.py
Traceback (most recent call last):
  File "/mnt/d/Alura/engenharia-dados-apache-airflow/datapipeline/.env/lib/python3.7/site-packages/airflow/models/dagbag.py", line 256, in process_file
    m = imp.load_source(mod_name, filepath)
  File "/home/felipe/anaconda3/lib/python3.7/imp.py", line 171, in load_source
    module = _load(spec)
  File "<frozen importlib._bootstrap>", line 696, in _load
  File "<frozen importlib._bootstrap>", line 677, in _load_unlocked
  File "<frozen importlib._bootstrap_external>", line 728, in exec_module
  File "<frozen importlib._bootstrap>", line 219, in _call_with_frames_removed
  File "/mnt/d/Alura/engenharia-dados-apache-airflow/datapipeline/airflow/dags/twitter_dag.py", line 4, in <module>
    from airflow.operators.alura import TwitterOperator
ModuleNotFoundError: No module named 'airflow.operators.alura'
[2022-02-02 20:54:35,662] {scheduler_job.py:1586} WARNING - No viable dags retrieved from /mnt/d/Alura/engenharia-dados-apache-airflow/datapipeline/airflow/dags/twitter_dag.py
[2022-02-02 20:54:35,672] {scheduler_job.py:163} INFO - Processing /mnt/d/Alura/engenharia-dados-apache-airflow/datapipeline/airflow/dags/twitter_dag.py took 0.016 seconds
[2022-02-02 20:55:27,682] {scheduler_job.py:155} INFO - Started process (PID=8180) to work on /mnt/d/Alura/engenharia-dados-apache-airflow/datapipeline/airflow/dags/twitter_dag.py
[2022-02-02 20:55:27,685] {scheduler_job.py:1572} INFO - Processing file /mnt/d/Alura/engenharia-dados-apache-airflow/datapipeline/airflow/dags/twitter_dag.py for tasks to queue
[2022-02-02 20:55:27,685] {logging_mixin.py:112} INFO - [2022-02-02 20:55:27,685] {dagbag.py:417} INFO - Filling up the DagBag from /mnt/d/Alura/engenharia-dados-apache-airflow/datapipeline/airflow/dags/twitter_dag.py
[2022-02-02 20:55:27,688] {logging_mixin.py:112} INFO - [2022-02-02 20:55:27,687] {dagbag.py:259} ERROR - Failed to import: /mnt/d/Alura/engenharia-dados-apache-airflow/datapipeline/airflow/dags/twitter_dag.py
Traceback (most recent call last):
  File "/mnt/d/Alura/engenharia-dados-apache-airflow/datapipeline/.env/lib/python3.7/site-packages/airflow/models/dagbag.py", line 256, in process_file
    m = imp.load_source(mod_name, filepath)
  File "/home/felipe/anaconda3/lib/python3.7/imp.py", line 171, in load_source
    module = _load(spec)
  File "<frozen importlib._bootstrap>", line 696, in _load
  File "<frozen importlib._bootstrap>", line 677, in _load_unlocked
  File "<frozen importlib._bootstrap_external>", line 728, in exec_module
  File "<frozen importlib._bootstrap>", line 219, in _call_with_frames_removed
  File "/mnt/d/Alura/engenharia-dados-apache-airflow/datapipeline/airflow/dags/twitter_dag.py", line 4, in <module>
    from airflow.operators.alura import TwitterOperator
ModuleNotFoundError: No module named 'airflow.operators.alura'
[2022-02-02 20:55:27,688] {scheduler_job.py:1586} WARNING - No viable dags retrieved from /mnt/d/Alura/engenharia-dados-apache-airflow/datapipeline/airflow/dags/twitter_dag.py
[2022-02-02 20:55:27,698] {scheduler_job.py:163} INFO - Processing /mnt/d/Alura/engenharia-dados-apache-airflow/datapipeline/airflow/dags/twitter_dag.py took 0.016 seconds
[2022-02-02 20:56:19,698] {scheduler_job.py:155} INFO - Started process (PID=8222) to work on /mnt/d/Alura/engenharia-dados-apache-airflow/datapipeline/airflow/dags/twitter_dag.py
[2022-02-02 20:56:19,701] {scheduler_job.py:1572} INFO - Processing file /mnt/d/Alura/engenharia-dados-apache-airflow/datapipeline/airflow/dags/twitter_dag.py for tasks to queue
[2022-02-02 20:56:19,701] {logging_mixin.py:112} INFO - [2022-02-02 20:56:19,701] {dagbag.py:417} INFO - Filling up the DagBag from /mnt/d/Alura/engenharia-dados-apache-airflow/datapipeline/airflow/dags/twitter_dag.py
[2022-02-02 20:56:19,704] {logging_mixin.py:112} INFO - [2022-02-02 20:56:19,703] {dagbag.py:259} ERROR - Failed to import: /mnt/d/Alura/engenharia-dados-apache-airflow/datapipeline/airflow/dags/twitter_dag.py
Traceback (most recent call last):
  File "/mnt/d/Alura/engenharia-dados-apache-airflow/datapipeline/.env/lib/python3.7/site-packages/airflow/models/dagbag.py", line 256, in process_file
    m = imp.load_source(mod_name, filepath)
  File "/home/felipe/anaconda3/lib/python3.7/imp.py", line 171, in load_source
    module = _load(spec)
  File "<frozen importlib._bootstrap>", line 696, in _load
  File "<frozen importlib._bootstrap>", line 677, in _load_unlocked
  File "<frozen importlib._bootstrap_external>", line 728, in exec_module
  File "<frozen importlib._bootstrap>", line 219, in _call_with_frames_removed
  File "/mnt/d/Alura/engenharia-dados-apache-airflow/datapipeline/airflow/dags/twitter_dag.py", line 4, in <module>
    from airflow.operators.alura import TwitterOperator
ModuleNotFoundError: No module named 'airflow.operators.alura'
[2022-02-02 20:56:19,704] {scheduler_job.py:1586} WARNING - No viable dags retrieved from /mnt/d/Alura/engenharia-dados-apache-airflow/datapipeline/airflow/dags/twitter_dag.py
[2022-02-02 20:56:19,719] {scheduler_job.py:163} INFO - Processing /mnt/d/Alura/engenharia-dados-apache-airflow/datapipeline/airflow/dags/twitter_dag.py took 0.021 seconds
[2022-02-02 20:57:11,717] {scheduler_job.py:155} INFO - Started process (PID=8256) to work on /mnt/d/Alura/engenharia-dados-apache-airflow/datapipeline/airflow/dags/twitter_dag.py
[2022-02-02 20:57:11,720] {scheduler_job.py:1572} INFO - Processing file /mnt/d/Alura/engenharia-dados-apache-airflow/datapipeline/airflow/dags/twitter_dag.py for tasks to queue
[2022-02-02 20:57:11,720] {logging_mixin.py:112} INFO - [2022-02-02 20:57:11,720] {dagbag.py:417} INFO - Filling up the DagBag from /mnt/d/Alura/engenharia-dados-apache-airflow/datapipeline/airflow/dags/twitter_dag.py
[2022-02-02 20:57:11,723] {logging_mixin.py:112} INFO - [2022-02-02 20:57:11,722] {dagbag.py:259} ERROR - Failed to import: /mnt/d/Alura/engenharia-dados-apache-airflow/datapipeline/airflow/dags/twitter_dag.py
Traceback (most recent call last):
  File "/mnt/d/Alura/engenharia-dados-apache-airflow/datapipeline/.env/lib/python3.7/site-packages/airflow/models/dagbag.py", line 256, in process_file
    m = imp.load_source(mod_name, filepath)
  File "/home/felipe/anaconda3/lib/python3.7/imp.py", line 171, in load_source
    module = _load(spec)
  File "<frozen importlib._bootstrap>", line 696, in _load
  File "<frozen importlib._bootstrap>", line 677, in _load_unlocked
  File "<frozen importlib._bootstrap_external>", line 728, in exec_module
  File "<frozen importlib._bootstrap>", line 219, in _call_with_frames_removed
  File "/mnt/d/Alura/engenharia-dados-apache-airflow/datapipeline/airflow/dags/twitter_dag.py", line 4, in <module>
    from airflow.operators.alura import TwitterOperator
ModuleNotFoundError: No module named 'airflow.operators.alura'
[2022-02-02 20:57:11,723] {scheduler_job.py:1586} WARNING - No viable dags retrieved from /mnt/d/Alura/engenharia-dados-apache-airflow/datapipeline/airflow/dags/twitter_dag.py
[2022-02-02 20:57:11,734] {scheduler_job.py:163} INFO - Processing /mnt/d/Alura/engenharia-dados-apache-airflow/datapipeline/airflow/dags/twitter_dag.py took 0.017 seconds
[2022-02-02 20:58:03,743] {scheduler_job.py:155} INFO - Started process (PID=8298) to work on /mnt/d/Alura/engenharia-dados-apache-airflow/datapipeline/airflow/dags/twitter_dag.py
[2022-02-02 20:58:03,746] {scheduler_job.py:1572} INFO - Processing file /mnt/d/Alura/engenharia-dados-apache-airflow/datapipeline/airflow/dags/twitter_dag.py for tasks to queue
[2022-02-02 20:58:03,746] {logging_mixin.py:112} INFO - [2022-02-02 20:58:03,746] {dagbag.py:417} INFO - Filling up the DagBag from /mnt/d/Alura/engenharia-dados-apache-airflow/datapipeline/airflow/dags/twitter_dag.py
[2022-02-02 20:58:03,749] {logging_mixin.py:112} INFO - [2022-02-02 20:58:03,748] {dagbag.py:259} ERROR - Failed to import: /mnt/d/Alura/engenharia-dados-apache-airflow/datapipeline/airflow/dags/twitter_dag.py
Traceback (most recent call last):
  File "/mnt/d/Alura/engenharia-dados-apache-airflow/datapipeline/.env/lib/python3.7/site-packages/airflow/models/dagbag.py", line 256, in process_file
    m = imp.load_source(mod_name, filepath)
  File "/home/felipe/anaconda3/lib/python3.7/imp.py", line 171, in load_source
    module = _load(spec)
  File "<frozen importlib._bootstrap>", line 696, in _load
  File "<frozen importlib._bootstrap>", line 677, in _load_unlocked
  File "<frozen importlib._bootstrap_external>", line 728, in exec_module
  File "<frozen importlib._bootstrap>", line 219, in _call_with_frames_removed
  File "/mnt/d/Alura/engenharia-dados-apache-airflow/datapipeline/airflow/dags/twitter_dag.py", line 4, in <module>
    from airflow.operators.alura import TwitterOperator
ModuleNotFoundError: No module named 'airflow.operators.alura'
[2022-02-02 20:58:03,749] {scheduler_job.py:1586} WARNING - No viable dags retrieved from /mnt/d/Alura/engenharia-dados-apache-airflow/datapipeline/airflow/dags/twitter_dag.py
[2022-02-02 20:58:03,759] {scheduler_job.py:163} INFO - Processing /mnt/d/Alura/engenharia-dados-apache-airflow/datapipeline/airflow/dags/twitter_dag.py took 0.016 seconds
[2022-02-02 20:58:55,766] {scheduler_job.py:155} INFO - Started process (PID=8340) to work on /mnt/d/Alura/engenharia-dados-apache-airflow/datapipeline/airflow/dags/twitter_dag.py
[2022-02-02 20:58:55,768] {scheduler_job.py:1572} INFO - Processing file /mnt/d/Alura/engenharia-dados-apache-airflow/datapipeline/airflow/dags/twitter_dag.py for tasks to queue
[2022-02-02 20:58:55,768] {logging_mixin.py:112} INFO - [2022-02-02 20:58:55,768] {dagbag.py:417} INFO - Filling up the DagBag from /mnt/d/Alura/engenharia-dados-apache-airflow/datapipeline/airflow/dags/twitter_dag.py
[2022-02-02 20:58:55,771] {logging_mixin.py:112} INFO - [2022-02-02 20:58:55,770] {dagbag.py:259} ERROR - Failed to import: /mnt/d/Alura/engenharia-dados-apache-airflow/datapipeline/airflow/dags/twitter_dag.py
Traceback (most recent call last):
  File "/mnt/d/Alura/engenharia-dados-apache-airflow/datapipeline/.env/lib/python3.7/site-packages/airflow/models/dagbag.py", line 256, in process_file
    m = imp.load_source(mod_name, filepath)
  File "/home/felipe/anaconda3/lib/python3.7/imp.py", line 171, in load_source
    module = _load(spec)
  File "<frozen importlib._bootstrap>", line 696, in _load
  File "<frozen importlib._bootstrap>", line 677, in _load_unlocked
  File "<frozen importlib._bootstrap_external>", line 728, in exec_module
  File "<frozen importlib._bootstrap>", line 219, in _call_with_frames_removed
  File "/mnt/d/Alura/engenharia-dados-apache-airflow/datapipeline/airflow/dags/twitter_dag.py", line 4, in <module>
    from airflow.operators.alura import TwitterOperator
ModuleNotFoundError: No module named 'airflow.operators.alura'
[2022-02-02 20:58:55,771] {scheduler_job.py:1586} WARNING - No viable dags retrieved from /mnt/d/Alura/engenharia-dados-apache-airflow/datapipeline/airflow/dags/twitter_dag.py
[2022-02-02 20:58:55,782] {scheduler_job.py:163} INFO - Processing /mnt/d/Alura/engenharia-dados-apache-airflow/datapipeline/airflow/dags/twitter_dag.py took 0.016 seconds
[2022-02-02 20:59:47,792] {scheduler_job.py:155} INFO - Started process (PID=8382) to work on /mnt/d/Alura/engenharia-dados-apache-airflow/datapipeline/airflow/dags/twitter_dag.py
[2022-02-02 20:59:47,795] {scheduler_job.py:1572} INFO - Processing file /mnt/d/Alura/engenharia-dados-apache-airflow/datapipeline/airflow/dags/twitter_dag.py for tasks to queue
[2022-02-02 20:59:47,795] {logging_mixin.py:112} INFO - [2022-02-02 20:59:47,795] {dagbag.py:417} INFO - Filling up the DagBag from /mnt/d/Alura/engenharia-dados-apache-airflow/datapipeline/airflow/dags/twitter_dag.py
[2022-02-02 20:59:47,798] {logging_mixin.py:112} INFO - [2022-02-02 20:59:47,797] {dagbag.py:259} ERROR - Failed to import: /mnt/d/Alura/engenharia-dados-apache-airflow/datapipeline/airflow/dags/twitter_dag.py
Traceback (most recent call last):
  File "/mnt/d/Alura/engenharia-dados-apache-airflow/datapipeline/.env/lib/python3.7/site-packages/airflow/models/dagbag.py", line 256, in process_file
    m = imp.load_source(mod_name, filepath)
  File "/home/felipe/anaconda3/lib/python3.7/imp.py", line 171, in load_source
    module = _load(spec)
  File "<frozen importlib._bootstrap>", line 696, in _load
  File "<frozen importlib._bootstrap>", line 677, in _load_unlocked
  File "<frozen importlib._bootstrap_external>", line 728, in exec_module
  File "<frozen importlib._bootstrap>", line 219, in _call_with_frames_removed
  File "/mnt/d/Alura/engenharia-dados-apache-airflow/datapipeline/airflow/dags/twitter_dag.py", line 4, in <module>
    from airflow.operators.alura import TwitterOperator
ModuleNotFoundError: No module named 'airflow.operators.alura'
[2022-02-02 20:59:47,798] {scheduler_job.py:1586} WARNING - No viable dags retrieved from /mnt/d/Alura/engenharia-dados-apache-airflow/datapipeline/airflow/dags/twitter_dag.py
[2022-02-02 20:59:47,809] {scheduler_job.py:163} INFO - Processing /mnt/d/Alura/engenharia-dados-apache-airflow/datapipeline/airflow/dags/twitter_dag.py took 0.017 seconds
